<?xml version="1.0" ?>
<sdf version="1.9">
  <model name="finalassembly_v3">
    <link name="base_link">
      <inertial>
        <mass>0.0001</mass>
        <inertia>
          <ixx>1e-09</ixx>
          <ixy>0</ixy>
          <ixz>0</ixz>
          <iyy>1e-09</iyy>
          <iyz>0</iyz>
          <izz>1e-09</izz>
        </inertia>
      </inertial>
    </link>
    <link name="base_link_1">
      <inertial>
        <pose>0.08000000000000008 0.09545598293362575 0.0068908634732035455 0.0 -0.0 0.0</pose>
        <mass>3.9409647200439992</mass>
        <inertia>
          <ixx>0.017709947701599185</ixx>
          <ixy>1.7694179454963432e-16</ixy>
          <ixz>-8.673617379884035e-19</ixz>
          <iyy>0.013743217946582138</iyy>
          <iyz>0.000759111480018366</iyz>
          <izz>0.0282437401639066</izz>
        </inertia>
      </inertial>
      <visual name="base_link_1__body1_visual">
        <geometry>
          <mesh>
            <scale>0.01 0.01 0.01</scale>
            <uri>meshes/base_link_1/body1_visual.obj</uri>
          </mesh>
        </geometry>
      </visual>
      <visual name="base_link_1__body2_visual">
        <geometry>
          <mesh>
            <scale>0.01 0.01 0.01</scale>
            <uri>meshes/base_link_1/body2_visual.obj</uri>
          </mesh>
        </geometry>
      </visual>
      <visual name="base_link_1__body3_visual">
        <geometry>
          <mesh>
            <scale>0.01 0.01 0.01</scale>
            <uri>meshes/base_link_1/body3_visual.obj</uri>
          </mesh>
        </geometry>
      </visual>
      <visual name="base_link_1__body4_visual">
        <geometry>
          <mesh>
            <scale>0.01 0.01 0.01</scale>
            <uri>meshes/base_link_1/body4_visual.obj</uri>
          </mesh>
        </geometry>
      </visual>
      <collision name="base_link_1__body1_collision">
        <pose relative_to="__model__">0.08 0.1 0.0025 -0.0 -1.5707963267948966 0</pose>
        <geometry>
          <box>
            <size>0.005 0.2 0.16</size>
          </box>
        </geometry>
      </collision>
      <collision name="base_link_1__body2_collision">
        <pose relative_to="__model__">0.08000000011523997 0.08252724989330502 0.024728898786180623 -1.5707962706113654 -1.452306371266263 1.570796383375153</pose>
        <geometry>
          <box>
            <size>0.0586927001989503 0.2379625470209429 0.16499999983791291</size>
          </box>
        </geometry>
      </collision>
      <collision name="base_link_1__body3_collision">
        <pose relative_to="__model__">0.14750000000000013 0.10000000269189624 -0.03881569860407179 -0.0 -1.5707963267948966 0</pose>
        <geometry>
          <box>
            <size>0.07763139720814398 0.18696152422706638 0.035</size>
          </box>
        </geometry>
      </collision>
      <collision name="base_link_1__body4_collision">
        <pose relative_to="__model__">0.012500000000000011 0.10000000269189552 -0.038815698604071976 -0.0 -1.5707963267948966 0</pose>
        <geometry>
          <box>
            <size>0.07763139720814409 0.18696152422706638 0.03499999999999998</size>
          </box>
        </geometry>
      </collision>
    </link>
    <link name="front_left_wheel_1">
      <inertial>
        <pose>0.18119913055959916 0.02650941058119064 -0.058006850665017165 0.0 -0.0 0.0</pose>
        <mass>0.23963195508574156</mass>
        <inertia>
          <ixx>0.00015999625746217466</ixx>
          <ixy>5.079204962437495e-10</ixy>
          <ixz>-4.011342529842976e-10</ixz>
          <iyy>0.00010144075867908435</iyy>
          <iyz>1.9240309589692653e-10</iyz>
          <izz>0.0001014408426342206</izz>
        </inertia>
      </inertial>
      <visual name="front_left_wheel_1__body1_visual">
        <geometry>
          <mesh>
            <scale>0.01 0.01 0.01</scale>
            <uri>meshes/front_left_wheel_1/body1_visual.obj</uri>
          </mesh>
        </geometry>
      </visual>
      <visual name="front_left_wheel_1__body2_visual">
        <geometry>
          <mesh>
            <scale>0.01 0.01 0.01</scale>
            <uri>meshes/front_left_wheel_1/body2_visual.obj</uri>
          </mesh>
        </geometry>
      </visual>
      <collision name="front_left_wheel_1__body1_collision">
        <pose relative_to="__model__">0.15527000000000016 0.0265096216351296 -0.058007041555161856 -0.0 -1.5707963267948966 0</pose>
        <geometry>
          <box>
            <size>0.007200000000000007 0.007199999999999997 0.03726000000000001</size>
          </box>
        </geometry>
      </collision>
      <collision name="front_left_wheel_1__body2_collision">
        <pose relative_to="__model__">0.18010000000000015 0.026509621635129533 -0.0580070415551619 -0.0 -1.5707963267948966 0</pose>
        <geometry>
          <box>
            <size>0.06500000000000003 0.06500000000000002 0.028200000000000003</size>
          </box>
        </geometry>
      </collision>
    </link>
    <link name="rear_left_wheel_1">
      <inertial>
        <pose>0.18119913055959913 0.17349016693742006 -0.05800685066501671 0.0 -0.0 0.0</pose>
        <mass>0.23963195508574073</mass>
        <inertia>
          <ixx>0.0001599965333883447</ixx>
          <ixy>2.5793205592206103e-10</ixy>
          <ixz>-4.0113425255061674e-10</ixz>
          <iyy>0.00010144075867908435</iyy>
          <iyz>2.7243130754778244e-10</iyz>
          <izz>0.00010144111856039313</izz>
        </inertia>
      </inertial>
      <visual name="rear_left_wheel_1__body1_visual">
        <geometry>
          <mesh>
            <scale>0.01 0.01 0.01</scale>
            <uri>meshes/rear_left_wheel_1/body1_visual.obj</uri>
          </mesh>
        </geometry>
      </visual>
      <visual name="rear_left_wheel_1__body2_visual">
        <geometry>
          <mesh>
            <scale>0.01 0.01 0.01</scale>
            <uri>meshes/rear_left_wheel_1/body2_visual.obj</uri>
          </mesh>
        </geometry>
      </visual>
      <collision name="rear_left_wheel_1__body1_collision">
        <pose relative_to="__model__">0.15527000000000013 0.17349038374866196 -0.05800704155516142 -0.0 -1.5707963267948966 0</pose>
        <geometry>
          <box>
            <size>0.007200000000000007 0.0071999999999999885 0.03726000000000001</size>
          </box>
        </geometry>
      </collision>
      <collision name="rear_left_wheel_1__body2_collision">
        <pose relative_to="__model__">0.1801000000000001 0.1734903837486619 -0.058007041555161475 -0.0 -1.5707963267948966 0</pose>
        <geometry>
          <box>
            <size>0.06500000000000003 0.065 0.028200000000000003</size>
          </box>
        </geometry>
      </collision>
    </link>
    <link name="front_right_wheel_1">
      <inertial>
        <pose>-0.021199138957676604 0.02650982708653022 -0.058006862365527455 0.0 -0.0 0.0</pose>
        <mass>0.23963191405046214</mass>
        <inertia>
          <ixx>0.0001599962599784674</ixx>
          <ixy>5.652733068683535e-10</ixy>
          <ixz>4.920400952998505e-10</ixz>
          <iyy>0.00010144045788691204</iyy>
          <iyz>-1.6255333477920367e-10</iyz>
          <izz>0.0001014405373198497</izz>
        </inertia>
      </inertial>
      <visual name="front_right_wheel_1__body1_visual">
        <geometry>
          <mesh>
            <scale>0.01 0.01 0.01</scale>
            <uri>meshes/front_right_wheel_1/body1_visual.obj</uri>
          </mesh>
        </geometry>
      </visual>
      <visual name="front_right_wheel_1__body2_visual">
        <geometry>
          <mesh>
            <scale>0.01 0.01 0.01</scale>
            <uri>meshes/front_right_wheel_1/body2_visual.obj</uri>
          </mesh>
        </geometry>
      </visual>
      <collision name="front_right_wheel_1__body1_collision">
        <pose relative_to="__model__">0.004730000000000029 0.026509621635128714 -0.05800704155516202 -0.0 -1.5707963267948966 0</pose>
        <geometry>
          <box>
            <size>0.007200000000000007 0.007200000000000007 0.03726000000000001</size>
          </box>
        </geometry>
      </collision>
      <collision name="front_right_wheel_1__body2_collision">
        <pose relative_to="__model__">-0.02009999999999998 0.026509621635128752 -0.058007041555162064 -0.0 -1.5707963267948966 0</pose>
        <geometry>
          <box>
            <size>0.06500000000000002 0.06500000000000002 0.028200000000000003</size>
          </box>
        </geometry>
      </collision>
    </link>
    <link name="rear_right_wheel_1">
      <inertial>
        <pose>-0.021199138957676535 0.17349058344363225 -0.05800686236552762 0.0 -0.0 0.0</pose>
        <mass>0.23963191405045922</mass>
        <inertia>
          <ixx>0.00015999653586396337</ixx>
          <ixy>5.945159233617867e-10</ixy>
          <ixz>4.920400964924729e-10</ixz>
          <iyy>0.00010144045788691063</iyy>
          <iyz>-8.253723659396028e-11</iyz>
          <izz>0.00010144081320534806</izz>
        </inertia>
      </inertial>
      <visual name="rear_right_wheel_1__body1_visual">
        <geometry>
          <mesh>
            <scale>0.01 0.01 0.01</scale>
            <uri>meshes/rear_right_wheel_1/body1_visual.obj</uri>
          </mesh>
        </geometry>
      </visual>
      <visual name="rear_right_wheel_1__body2_visual">
        <geometry>
          <mesh>
            <scale>0.01 0.01 0.01</scale>
            <uri>meshes/rear_right_wheel_1/body2_visual.obj</uri>
          </mesh>
        </geometry>
      </visual>
      <collision name="rear_right_wheel_1__body1_collision">
        <pose relative_to="__model__">0.004730000000000003 0.1734903837486623 -0.05800704155516154 -0.0 -1.5707963267948966 0</pose>
        <geometry>
          <box>
            <size>0.007200000000000007 0.0071999999999999885 0.037260000000000015</size>
          </box>
        </geometry>
      </collision>
      <collision name="rear_right_wheel_1__body2_collision">
        <pose relative_to="__model__">-0.02010000000000012 0.173490383748662 -0.058007041555162404 -0.0 -1.5707963267948966 0</pose>
        <geometry>
          <box>
            <size>0.06500000000000002 0.06499999999999999 0.028200000000000412</size>
          </box>
        </geometry>
      </collision>
    </link>
    <joint name="revolute_1" type="continuous">
      <pose relative_to="__model__">0.16500000000000015 0.02650962163512962 -0.0580070415551618 0.0 -0.0 0.0</pose>
      <parent>base_link_1</parent>
      <child>front_left_wheel_1</child>
      <axis>
        <xyz expressed_in="__model__">0.9999999999999996 0.0 5.117292425077455e-16</xyz>
      </axis>
    </joint>
    <joint name="revolute_2" type="continuous">
      <pose relative_to="__model__">0.16500000000000015 0.17349038374866205 -0.05800704155516137 0.0 -0.0 0.0</pose>
      <parent>base_link_1</parent>
      <child>rear_left_wheel_1</child>
      <axis>
        <xyz expressed_in="__model__">-0.9999999999999996 0.0 -5.117292425077455e-16</xyz>
      </axis>
    </joint>
    <joint name="revolute_3" type="continuous">
      <pose relative_to="__model__">-0.004999999999999974 0.02650962163512876 -0.05800704155516197 0.0 -0.0 0.0</pose>
      <parent>base_link_1</parent>
      <child>front_right_wheel_1</child>
      <axis>
        <xyz expressed_in="__model__">1.0000000000000013 0.0 -5.012406971746356e-16</xyz>
      </axis>
    </joint>
    <joint name="revolute_4" type="continuous">
      <pose relative_to="__model__">-0.004999999999999996 0.1734903837486621 -0.058007041555161905 0.0 -0.0 0.0</pose>
      <parent>base_link_1</parent>
      <child>rear_right_wheel_1</child>
      <axis>
        <xyz expressed_in="__model__">1.0000000000000013 0.0 -5.012406971746356e-16</xyz>
      </axis>
    </joint>
  </model>
</sdf>
