<?xml version="1.0" ?>
<sdf version="1.9">
  <model name="finalassembly_v3">
    
    <link name="base_link_1">
      <inertial>
        <pose>0.08000000000000008 0.09545598293362575 0.0068908634732035455 0.0 -0.0 0.0</pose>
        <mass>3.9409647200439992</mass>
        <inertia>
          <ixx>0.017709947701599185</ixx>
          <ixy>1.7694179454963432e-16</ixy>
          <ixz>-8.673617379884035e-19</ixz>
          <iyy>0.013743217946582138</iyy>
          <iyz>0.000759111480018366</iyz>
          <izz>0.0282437401639066</izz>
        </inertia>
      </inertial>

      <visual name="base_link_1__body1_visual">
        <geometry>
          <mesh>
            <scale>0.05 0.05 0.05</scale>
            <uri>meshes/base_link_1/body1_visual.obj</uri>
          </mesh>
        </geometry>
      </visual>

      <visual name="base_link_1__body2_visual">
        <geometry>
          <mesh>
            <scale>0.05 0.05 0.05</scale>
            <uri>meshes/base_link_1/body2_visual.obj</uri>
          </mesh>
        </geometry>
      </visual>

      <visual name="base_link_1__body3_visual">
        <geometry>
          <mesh>
            <scale>0.05 0.05 0.05</scale>
            <uri>meshes/base_link_1/body3_visual.obj</uri>
          </mesh>
        </geometry>
      </visual>

      <visual name="base_link_1__body4_visual">
        <geometry>
          <mesh>
            <scale>0.05 0.05 0.05</scale>
            <uri>meshes/base_link_1/body4_visual.obj</uri>
          </mesh>
        </geometry>
      </visual>

      <collision name="base_link_collision">
        <pose>0.40 0.40 0.075 0 0 0</pose>
        <geometry>
          <box>
            <size>0.80 1.20 0.40</size>
          </box>
        </geometry>
      </collision>
    </link>


    <link name="front_left_wheel_1">
      <inertial>
        <pose>0.18119913055959916 0.02650941058119064 -0.058006850665017165 0.0 -0.0 0.0</pose>
        <mass>0.23963195508574156</mass>
        <inertia>
          <ixx>0.00015999625746217466</ixx>
          <ixy>5.079204962437495e-10</ixy>
          <ixz>-4.011342529842976e-10</ixz>
          <iyy>0.00010144075867908435</iyy>
          <iyz>1.9240309589692653e-10</iyz>
          <izz>0.0001014408426342206</izz>
        </inertia>
      </inertial>

      <visual name="front_left_wheel_1__body1_visual">
        <geometry>
          <mesh>
            <scale>0.05 0.05 0.05</scale>
            <uri>meshes/front_left_wheel_1/body1_visual.obj</uri>
          </mesh>
        </geometry>
      </visual>

      <visual name="front_left_wheel_1__body2_visual">
        <geometry>
          <mesh>
            <scale>0.05 0.05 0.05</scale>
            <uri>meshes/front_left_wheel_1/body2_visual.obj</uri>
          </mesh>
        </geometry>
      </visual>

      <collision name="wheel_collision">
        <pose>0.9005 0.1325 -0.29 1.5708 0 1.5708</pose>
        <geometry>
          <cylinder>
            <radius>0.16</radius>
            <length>0.14</length>
          </cylinder>
        </geometry>
      </collision>
    </link>


    <link name="rear_left_wheel_1">
      <inertial>
        <pose>0.18119913055959913 0.17349016693742006 -0.05800685066501671 0.0 -0.0 0.0</pose>
        <mass>0.23963195508574073</mass>
        <inertia>
          <ixx>0.0001599965333883447</ixx>
          <ixy>2.5793205592206103e-10</ixy>
          <ixz>-4.0113425255061674e-10</ixz>
          <iyy>0.00010144075867908435</iyy>
          <iyz>2.7243130754778244e-10</iyz>
          <izz>0.00010144111856039313</izz>
        </inertia>
      </inertial>

      <visual name="rear_left_wheel_1__body1_visual">
        <geometry>
          <mesh>
            <scale>0.05 0.05 0.05</scale>
            <uri>meshes/rear_left_wheel_1/body1_visual.obj</uri>
          </mesh>
        </geometry>
      </visual>

      <visual name="rear_left_wheel_1__body2_visual">
        <geometry>
          <mesh>
            <scale>0.05 0.05 0.05</scale>
            <uri>meshes/rear_left_wheel_1/body2_visual.obj</uri>
          </mesh>
        </geometry>
      </visual>

      <collision name="wheel_collision">
        <pose>0.9005 0.8675 -0.29 1.5708 0 1.5708</pose>
        <geometry>
          <cylinder>
            <radius>0.16</radius>
            <length>0.14</length>
          </cylinder>
        </geometry>
      </collision>
    </link>


    <link name="front_right_wheel_1">
      <inertial>
        <pose>-0.021199138957676604 0.02650982708653022 -0.058006862365527455 0.0 -0.0 0.0</pose>
        <mass>0.23963191405046214</mass>
        <inertia>
          <ixx>0.0001599962599784674</ixx>
          <ixy>5.652733068683535e-10</ixy>
          <ixz>4.920400952998505e-10</ixz>
          <iyy>0.00010144045788691204</iyy>
          <iyz>-1.6255333477920367e-10</iyz>
          <izz>0.0001014405373198497</izz>
        </inertia>
      </inertial>

      <visual name="front_right_wheel_1__body1_visual">
        <geometry>
          <mesh>
            <scale>0.05 0.05 0.05</scale>
            <uri>meshes/front_right_wheel_1/body1_visual.obj</uri>
          </mesh>
        </geometry>
      </visual>

      <visual name="front_right_wheel_1__body2_visual">
        <geometry>
          <mesh>
            <scale>0.05 0.05 0.05</scale>
            <uri>meshes/front_right_wheel_1/body2_visual.obj</uri>
          </mesh>
        </geometry>
      </visual>

      <collision name="wheel_collision">
        <pose>-0.1005 0.1325 -0.29 1.5708 0 1.5708</pose>
        <geometry>
          <cylinder>
            <radius>0.16</radius>
            <length>0.14</length>
          </cylinder>
        </geometry>
      </collision>
    </link>


    <link name="rear_right_wheel_1">
      <inertial>
        <pose>-0.021199138957676535 0.17349058344363225 -0.05800686236552762 0.0 -0.0 0.0</pose>
        <mass>0.23963191405045922</mass>
        <inertia>
          <ixx>0.00015999653586396337</ixx>
          <ixy>5.945159233617867e-10</ixy>
          <ixz>4.920400964924729e-10</ixz>
          <iyy>0.00010144045788691063</iyy>
          <iyz>-8.253723659396028e-11</iyz>
          <izz>0.00010144081320534806</izz>
        </inertia>
      </inertial>

      <visual name="rear_right_wheel_1__body1_visual">
        <geometry>
          <mesh>
            <scale>0.05 0.05 0.05</scale>
            <uri>meshes/rear_right_wheel_1/body1_visual.obj</uri>
          </mesh>
        </geometry>
      </visual>

      <visual name="rear_right_wheel_1__body2_visual">
        <geometry>
          <mesh>
            <scale>0.05 0.05 0.05</scale>
            <uri>meshes/rear_right_wheel_1/body2_visual.obj</uri>
          </mesh>
        </geometry>
      </visual>

      <collision name="wheel_collision">
        <pose>-0.1005 0.8675 -0.29 1.5708 0 1.5708</pose>
        <geometry>
          <cylinder>
            <radius>0.16</radius>
            <length>0.14</length>
          </cylinder>
        </geometry>
      </collision>
    </link>


    <joint name="front_left_joint" type="revolute">
      <pose>0.165 0.0265 -0.058 0 0 0</pose>
      <parent>base_link_1</parent>
      <child>front_left_wheel_1</child>
      <axis>
        <xyz>1 0 0</xyz>
        <limit>
          <lower>-1000000</lower>
          <upper>1000000</upper>
        </limit>
      </axis>
    </joint>

    <joint name="rear_left_joint" type="revolute">
      <pose>0.165 0.1735 -0.058 0 0 0</pose>
      <parent>base_link_1</parent>
      <child>rear_left_wheel_1</child>
      <axis>
        <xyz>1 0 0</xyz>
        <limit>
          <lower>-1000000</lower>
          <upper>1000000</upper>
        </limit>
      </axis>
    </joint>

    <joint name="front_right_joint" type="revolute">
      <pose>-0.005 0.0265 -0.058 0 0 0</pose>
      <parent>base_link_1</parent>
      <child>front_right_wheel_1</child>
      <axis>
        <xyz>1 0 0</xyz>
        <limit>
          <lower>-1000000</lower>
          <upper>1000000</upper>
        </limit>
      </axis>
    </joint>

    <joint name="rear_right_joint" type="revolute">
      <pose>-0.005 0.1735 -0.058 0 0 0</pose>
      <parent>base_link_1</parent>
      <child>rear_right_wheel_1</child>
      <axis>
        <xyz>1 0 0</xyz>
        <limit>
          <lower>-1000000</lower>
          <upper>1000000</upper>
        </limit>
      </axis>
    </joint>

  </model>
</sdf>